2025-01-22 00:00:26.523 | INFO     | __main__:do_listen_and_comment:305 - sensevoice 模型加载中，请稍后...
2025-01-22 00:00:32.166 | INFO     | __main__:do_listen_and_comment:335 - sensevoice 模型加载完毕，可以开始说话了喵~
2025-01-22 00:00:36.181 | ERROR    | __main__:do_listen_and_comment:409 - Traceback (most recent call last):
  File "J:\code\SenseVoice\demo1.py", line 375, in do_listen_and_comment
    with wave.open(WAVE_OUTPUT_FILENAME, "wb") as wf:
         ^^^^^^^^^^^^^^^^^^^^^^^^^^^^^^^^^^^^^
  File "c:\Users\fantasticman\.conda\envs\chatBot\Lib\wave.py", line 632, in open
    return Wave_write(f)
           ^^^^^^^^^^^^^
  File "c:\Users\fantasticman\.conda\envs\chatBot\Lib\wave.py", line 425, in __init__
    f = builtins.open(f, 'wb')
        ^^^^^^^^^^^^^^^^^^^^^^
FileNotFoundError: [Errno 2] No such file or directory: 'J:\\code\\SenseVoice\\out\\asr_2.wav'

2025-01-22 00:01:35.629 | INFO     | __main__:do_listen_and_comment:305 - sensevoice 模型加载中，请稍后...
2025-01-22 00:01:40.815 | INFO     | __main__:do_listen_and_comment:335 - sensevoice 模型加载完毕，可以开始说话了喵~
2025-01-22 00:01:44.093 | INFO     | __main__:talk_handle:182 - 识别结果：嗯嗯
2025-01-22 00:01:46.932 | INFO     | __main__:talk_handle:182 - 识别结果：继息
2025-01-22 00:01:51.474 | INFO     | __main__:talk_handle:182 - 识别结果：哎识别不对呀
